Workbook
Name \a: #REF!
Name \a: #REF!
Name \b: #REF!
Name \b: #REF!
Name \c: #REF!
Name \c: #REF!
Name \n: #REF!
Name \n: #REF!
Name \o: #REF!
Name \o: #REF!
Name _01: [1]Presupuesto!#REF!
Name _01: [1]Presupuesto!#REF!
Name _02: [1]Presupuesto!#REF!
Name _02: [1]Presupuesto!#REF!
Name _03: [1]Presupuesto!#REF!
Name _03: [1]Presupuesto!#REF!
Name _04: [1]Presupuesto!#REF!
Name _04: [1]Presupuesto!#REF!
Name _05: [1]Presupuesto!#REF!
Name _05: [1]Presupuesto!#REF!
Name _06: [1]Presupuesto!#REF!
Name _06: [1]Presupuesto!#REF!
Name _07: [1]Presupuesto!#REF!
Name _07: [1]Presupuesto!#REF!
Name _08: [1]Presupuesto!#REF!
Name _08: [1]Presupuesto!#REF!
Name _09: [1]Presupuesto!#REF!
Name _09: [1]Presupuesto!#REF!
Name _10: [1]Presupuesto!#REF!
Name _10: [1]Presupuesto!#REF!
Name _11: [1]Presupuesto!#REF!
Name _11: [1]Presupuesto!#REF!
Name _12: [1]Presupuesto!#REF!
Name _12: [1]Presupuesto!#REF!
Name _13: [1]Presupuesto!#REF!
Name _13: [1]Presupuesto!#REF!
Name _14: [1]Presupuesto!#REF!
Name _14: [1]Presupuesto!#REF!
Name _15: [1]Presupuesto!#REF!
Name _15: [1]Presupuesto!#REF!
Name _16: [1]Presupuesto!#REF!
Name _16: [1]Presupuesto!#REF!
Name _17: [1]Presupuesto!#REF!
Name _17: [1]Presupuesto!#REF!
Name _18: [1]Presupuesto!#REF!
Name _18: [1]Presupuesto!#REF!
Name _19: [1]Presupuesto!#REF!
Name _19: [1]Presupuesto!#REF!
Name _20: [1]Presupuesto!#REF!
Name _20: [1]Presupuesto!#REF!
Name _21: [1]Presupuesto!#REF!
Name _21: [1]Presupuesto!#REF!
Name _22: [1]Presupuesto!#REF!
Name _22: [1]Presupuesto!#REF!
Name _23: [1]Presupuesto!#REF!
Name _23: [1]Presupuesto!#REF!
Name _24: [1]Presupuesto!#REF!
Name _24: [1]Presupuesto!#REF!
Name _25: [1]Presupuesto!#REF!
Name _25: [1]Presupuesto!#REF!

Sheet PPTO ESTUDIO TV
BL2: PRESUPUESTO RESUMEN | BP2: =+$M$128 -> 1.588966
I3: SUP CUB. | J3: =SUM(J1:J2) -> 0 | BL3: ESTUDIO TV
P4: 1 - TRABAJOS PREPARATORIOS | X4: 4 - ESTRUCTURA RESISTENTE | AF4: 5 - MAMPOSTERIA | AN4: 10 - TABIQUE DE PLACAS DE YESO | AW4: 15 - INSTALACIÓN ELECTROMECÁNICA | BD4: 18 - VARIOS | BL4: LOCALIDAD: RESISTENCIA
E5: ESTUDIO TV | P5: 1.1 - TRASLADO DE MUEBLES, CUADROS, PAPELERIA, ETC | T5: =$G$13 -> Gl | U5: =$H$13 -> 1 | X5: 4.1.1 - HºAº PARA BASE ASCENSOR - H30 | AB5: =$G$27 -> m3 | AC5: =$H$27 -> 1.878225 | AF5: 5.1 - MAMP. ELEVACION LAD.COMUN - 0,18 | AJ5: =$G$41 -> m3 | AK5: =$H$41 -> 35.11 | AN5: 10.1 - TABIQUE DE PLACA DE YESO - DOBLE PLACA, LANA DE VIDRIO 70mm-ESTUDIO | AR5: =$G$59 -> m2 | AS5: =$H$59 -> 358.7 | AW5: 15.1 - ASCENSOR | BA5: =$G$101 -> Gl | BB5: =$H$101 -> 1 | BD5: 18.1 - LIMPIEZA DE OBRA | BH5: =$G$112 -> Gl | BI5: =$H$112 -> 1 | BL5: EMPRESA: I.L.A.G. CONSTRUCCIONES
E6: LOCALIDAD: RESISTENCIA
E7: EMPRESA: I.L.A.G. CONSTRUCCIONES | P7: DESCRIPCION | Q7: UNIDAD | R7: CANTIDAD | S7: PRECIO | T7: Subtotal | U7: FLETE | X7: DESCRIPCION | Y7: UNIDAD | Z7: CANTIDAD | AA7: PRECIO | AB7: Subtotal | AC7: FLETE | AF7: DESCRIPCION | AG7: UNIDAD | AH7: CANTIDAD | AI7: PRECIO | AJ7: Subtotal | AK7: FLETE | AN7: DESCRIPCION | AO7: UNIDAD | AP7: CANTIDAD | AQ7: PRECIO | AR7: Subtotal | AS7: FLETE | AW7: DESCRIPCION | AX7: UNIDAD | AY7: CANTIDAD | AZ7: PRECIO | BA7: Subtotal | BB7: FLETE | BD7: DESCRIPCION | BE7: UNIDAD | BF7: CANTIDAD | BG7: PRECIO | BH7: Subtotal | BI7: FLETE | BL7: Nº DE | BM7: DESIGNACION DE LA OBRA | BN7: PRECIO TOTAL | BO7: INCIDENCIA
E8: COMPUTO Y PRESUPUESTO | P8: Materiales: | X8: Materiales: | AF8: Materiales: | AN8: Materiales: | AW8: Materiales: | BD8: Materiales: | BL8: ITEMS | BO8: % TOTAL
T9: =+ROUND(R9*S9,2) -> 0 | X9: Hormigón Elaborado H-30 | Y9: m3 | Z9: 1.1 | AA9: 27425 | AB9: =+ROUND(Z9*AA9,2) -> 30167.5 | AF9: Ladrillos Comunes | AG9: Un | AH9: 290 | AI9: 37.45 | AJ9: =+ROUND(AH9*AI9,2) -> 10860.5 | AN9: TABIQUE DE PLACA DE YESO - DOBLE PLACA, LANA DE VIDRIO 70mm-ESTUDIO | AO9: m2 | AP9: 1.05 | AQ9: 31126.3 | AR9: =+ROUND(AP9*AQ9,2) -> 32682.62 | AW9: ASCENSOR HIDRAULICO LATERAL R PARADAS | AX9: GL | AY9: 1 | AZ9: 13504596 | BA9: =+ROUND(AY9*AZ9,2) -> 13504596 | BH9: =ROUND((BG9*BF9),2) -> 0
E10: RUBRO | F10: DESCRIPCION | G10: UN | H10: CANTIDAD | I10: COSTO UNIT | J10: COSTO ITEM | K10: TOTAL RUBRO | L10: % INCIDENCIA | T10: =+ROUND(R10*S10,2) -> 0 | X10: Hierro | Y10: Kg | Z10: 120 | AA10: 390.35069 | AB10: =+ROUND(Z10*AA10,2) -> 46842.08 | AF10: Cemento | AG10: Kg | AH10: 90 | AI10: 26.528938 | AJ10: =+ROUND(AH10*AI10,2) -> 2387.6 | AN10: Varios, carga, descarga y desperdicio | AO10: gl | AP10: 0.03 | AQ10: 32682.62 | AR10: =+ROUND(AP10*AQ10,2) -> 980.48 | AW10: VARIOS CONEXIONADO | AX10: GL | AY10: 1 | AZ10: 94532.172 | BA10: =+ROUND(AY10*AZ10,2) -> 94532.17 | BH10: =ROUND((BG10*BF10),2) -> 0 | BL10: =+$E$12 -> 1 | BM10: =$F$12 -> TRABAJOS PREPARATORIOS | BN10: =+$K$12*$BP$2 -> 452975.52 | BO10: =BN10/$BN$30 -> 0.0014978125
P11: SUBTOTAL MATERIALES - A - | T11: =SUM(T9:T10) -> 0 | X11: Alambre | Y11: Kg | Z11: 1 | AA11: 739.04185 | AB11: =+ROUND(Z11*AA11,2) -> 739.04 | AF11: Arena | AG11: M3 | AH11: 0.36 | AI11: 2066.1157 | AJ11: =+ROUND(AH11*AI11,2) -> 743.8 | AN11: SUBTOTAL MATERIALES - A - | AR11: =SUM(AR9:AR10) -> 33663.1 | AW11: Varios, carga, descarga y desperdicio | AX11: gl | AY11: 0.03 | AZ11: 13599128 | BA11: =+ROUND(AY11*AZ11,2) -> 407973.85 | BD11: Varios, carga, descarga y desperdicio | BE11: gl | BF11: 0.03 | BG11: 0 | BH11: =ROUND((BG11*BF11),2) -> 0 | BL11: =+$E$15 -> 2 | BM11: =$F$15 -> DEMOLICIONES | BN11: =+$K$15*$BP$2 -> 622029.59 | BO11: =BN11/$BN$30 -> 0.0020568081
E12: 1 | F12: TRABAJOS PREPARATORIOS | K12: =SUM(J13:J14) -> 285075.66 | L12: =+K12/$K$120 -> 0.0014978125 | P12: Mano de Obra: | X12: Clavos | Y12: Kg | Z12: 1 | AA12: 684.56365 | AB12: =+ROUND(Z12*AA12,2) -> 684.56 | AF12: Hierro | AG12: Kg | AH12: 1.05 | AI12: 27.236208 | AJ12: =+ROUND(AH12*AI12,2) -> 28.6 | AN12: Mano de Obra: | AW12: SUBTOTAL MATERIALES - A - | BA12: =SUM(BA9:BA11) -> 14007102 | BD12: SUBTOTAL MATERIALES - A - | BH12: =SUM(BH9:BH11) -> 0 | BL12: =+$E$23 -> 3 | BM12: =$F$23 -> MOVIMIENTO DE SUELO | BN12: =+$K$23*$BP$2 -> 113182.63 | BO12: =BN12/$BN$30 -> 0.0003742506
E13: 1.1 | F13: TRASLADO DE MUEBLES, CUADROS, PAPELERIA, ETC | G13: Gl | H13: 1 | I13: =+$T$23 -> 121923 | J13: =ROUND(I13*H13,2) -> 121923 | L13: =+J13/$K$120 -> 0.00064059412 | M13: =+L13 -> 0.00064059412 | P13: Oficial | Q13: hs | S13: 1600.8 | T13: =+ROUND(R13*S13,2) -> 0 | X13: Encofrado | Y13: m2 | Z13: 1.1 | AA13: 3370 | AB13: =+ROUND(Z13*AA13,2) -> 3707 | AF13: Varios, carga, descarga y desperdicio | AG13: gl | AH13: 0.03 | AI13: 14020.5 | AJ13: =+ROUND(AH13*AI13,2) -> 420.62 | AN13: Oficial | AO13: hs | AQ13: 1600.8 | AR13: =+ROUND(AP13*AQ13,2) -> 0 | AW13: Mano de Obra: | BD13: Mano de Obra: | BL13: =+$E$25 -> 4 | BM13: =$F$25 -> ESTRUCTURA RESISTENTE | BN13: =+$K$25*$BP$2 -> 21249056 | BO13: =BN13/$BN$30 -> 0.070262299
E14: 1.2 | F14: CARTEL DE OBRA | G14: m2 | H14: 8.64 | I14: =+$T$44 -> 18883.41 | J14: =ROUND(I14*H14,2) -> 163152.66 | L14: =+J14/$K$120 -> 0.00085721837 | M14: =+L14 -> 0.00085721837 | P14: Ayudante | Q14: hs | R14: 90 | S14: 1354.7 | T14: =+ROUND(R14*S14,2) -> 121923 | X14: Varios, carga, descarga y desperdicio | Y14: gl | Z14: 0.03 | AA14: 51972.68 | AB14: =+ROUND(Z14*AA14,2) -> 1559.18 | AF14: SUBTOTAL MATERIALES - A - | AJ14: =SUM(AJ9:AJ13) -> 14441.12 | AN14: Ayudante | AO14: hs | AQ14: 1354.7 | AR14: =+ROUND(AP14*AQ14,2) -> 0 | AW14: Oficial | AX14: hs | AY14: 40 | AZ14: 1600.8 | BA14: =+ROUND(AY14*AZ14,2) -> 64032 | BD14: Oficial | BE14: hs | BG14: 1600.8 | BH14: =+ROUND(BF14*BG14,2) -> 0 | BL14: =+$E$40 -> 5 | BM14: =$F$40 -> MAMPOSTERIA | BN14: =+$K$40*$BP$2 -> 2318511.6 | BO14: =BN14/$BN$30 -> 0.0076664091
E15: 2 | F15: DEMOLICIONES | K15: =SUM(J16:J22) -> 391468.17 | L15: =+K15/$K$120 -> 0.0020568081 | X15: SUBTOTAL MATERIALES - A - | AB15: =SUM(AB9:AB14) -> 83699.36 | AF15: Mano de Obra: | AW15: Ayudante | AX15: hs | AY15: 40 | AZ15: 1354.7 | BA15: =+ROUND(AY15*AZ15,2) -> 54188 | BD15: Ayudante | BE15: hs | BF15: 120 | BG15: 1354.7 | BH15: =+ROUND(BF15*BG15,2) -> 162564 | BL15: =+$E$45 -> 6 | BM15: =$F$45 -> AISLACION | BN15: =+$K$45*$BP$2 -> 2548672 | BO15: =BN15/$BN$30 -> 0.0084274593
E16: 2.1 | F16: DEMOLICION DE CIELORRASO EXISTENTE | G16: m2 | H16: 289.58 | I16: =+$T$62 -> 547.76 | J16: =ROUND(I16*H16,2) -> 158620.34 | L16: =+J16/$K$120 -> 0.00083340516 | M16: =+L16 -> 0.00083340516 | P16: SUBTOTAL MANO DE OBRA - B - | T16: =SUM(T13:T15) -> 121923 | X16: Mano de Obra: | AF16: Oficial | AG16: hs | AH16: 8 | AI16: 1600.8 | AJ16: =+ROUND(AH16*AI16,2) -> 12806.4 | AN16: SUBTOTAL MANO DE OBRA - B - | AR16: =SUM(AR13:AR15) -> 0 | BL16: =+$E$48 -> 7 | BM16: =$F$48 -> REVOQUE | BN16: =+$K$48*$BP$2 -> 2406120.7 | BO16: =BN16/$BN$30 -> 0.0079560982
E17: 2.2 | F17: RETIRO DE CARPINTERIAS EXISTENTES | G17: Un | H17: 2 | I17: =+$T$80 -> 3171.11 | J17: =ROUND(I17*H17,2) -> 6342.22 | L17: =+J17/$K$120 -> 3.3322579e-05 | M17: =+L17 -> 3.3322579e-05 | X17: Oficial | Y17: hs | Z17: 12 | AA17: 1600.8 | AB17: =+ROUND(Z17*AA17,2) -> 19209.6 | AF17: Ayudante | AG17: hs | AH17: 8 | AI17: 1354.7 | AJ17: =+ROUND(AH17*AI17,2) -> 10837.6 | AN17: Equipos: | AW17: SUBTOTAL MANO DE OBRA - B - | BA17: =SUM(BA14:BA16) -> 118220 | BB17: =+BA17/BA12 -> 0.0084400042 | BD17: SUBTOTAL MANO DE OBRA - B - | BH17: =SUM(BH14:BH16) -> 162564 | BL17: =+$E$52 -> 8 | BM17: =$F$52 -> REVESTIMIENTO | BN17: =+$K$52*$BP$2 -> 34097.032 | BO17: =BN17/$BN$30 -> 0.00011274552
E18: 2.3 | F18: RETIRO DE PAÑOS VIDRIADOS P/ OFICINAS | G18: m2 | H18: 23.04 | I18: =+T98 -> 1915.51 | J18: =ROUND(I18*H18,2) -> 44133.35 | L18: =+J18/$K$120 -> 0.00023188049 | M18: =+L18 -> 0.00023188049 | P18: Equipos: | X18: Ayudante | Y18: hs | Z18: 12 | AA18: 1354.7 | AB18: =+ROUND(Z18*AA18,2) -> 16256.4 | AN18: FLETE | AO18: KG | AP18: 60 | AQ18: 1.9600688 | AR18: =+ROUND(AP18*AQ18,2) -> 117.6 | AW18: Equipos: | BD18: Equipos: | BL18: =+$E$54 -> 9 | BM18: =$F$54 -> CUBIERTA DE CHº Gº | BN18: =+$K$54*$BP$2 -> 1304592.9 | BO18: =BN18/$BN$30 -> 0.0043137775
E19: 2.4 | F19: RETIRO DE BARANDAS EXISTENTES EN TERRAZA | G19: ml | H19: 18.77 | I19: =+$T$116 -> 470.22 | J19: =ROUND(I19*H19,2) -> 8826.03 | L19: =+J19/$K$120 -> 4.6372735e-05 | M19: =+L19 -> 4.6372735e-05 | P19: FLETE | Q19: KG | R19: 0 | S19: 1.9600688 | T19: =+ROUND(R19*S19,2) -> 0 | AF19: SUBTOTAL MANO DE OBRA - B - | AJ19: =SUM(AJ16:AJ18) -> 23644 | AN19: SUBTOTAL EQUIPOS - C - | AR19: =SUM(AR18:AR18) -> 117.6 | AW19: FLETE | AX19: KG | AY19: 360 | AZ19: 1.9600688 | BA19: =+ROUND(AY19*AZ19,2) -> 705.62 | BD19: FLETE | BE19: KG | BF19: 0 | BG19: 1.9600688 | BH19: =+ROUND(BF19*BG19,2) -> 0 | BL19: =+$E$58 -> 10 | BM19: =$F$58 -> TABIQUE DE PLACAS DE YESO | BN19: =+$K$58*$BP$2 -> 21201331 | BO19: =BN19/$BN$30 -> 0.07010449
E20: 2.5 | F20: DEMOLICION DE PISO Y CONTRAPISO P/ ASCENSOR | G20: m2 | H20: 5.681 | I20: =+$T$135 -> 860.5 | J20: =ROUND(I20*H20,2) -> 4888.5 | L20: =+J20/$K$120 -> 2.5684607e-05 | M20: =+L20 -> 2.5684607e-05 | P20: Equipos - Hormigonera | Q20: gl | S20: 686.94 | T20: =+ROUND(R20*S20,2) -> 0 | X20: SUBTOTAL MANO DE OBRA - B - | AB20: =SUM(AB17:AB19) -> 35466 | AF20: Equipos: | AN20: COSTO NETO TOTAL - D - | AP20: (A+B+C) | AR20: =+AR11+AR16+AR19 -> 33780.7 | AW20: SUBTOTAL EQUIPOS - C - | BA20: =SUM(BA19:BA19) -> 705.62 | BD20: CONTENEDOR | BE20: un | BF20: 60 | BG20: 5500 | BH20: =+ROUND(BF20*BG20,2) -> 330000 | BL20: =+$E$61 -> 11 | BM20: =$F$61 -> CIELORRASO | BN20: =+$K$61*$BP$2 -> 7141716 | BO20: =BN20/$BN$30 -> 0.023614856
E21: 2.6 | F21: DEMOLICION DE PISO DE TERRAZA | G21: m2 | H21: 87.4469 | I21: =+$T$154 -> 703.69 | J21: =ROUND(I21*H21,2) -> 61535.51 | L21: =+J21/$K$120 -> 0.00032331296 | M21: =+L21 -> 0.00032331296 | T21: =+ROUND(R21*S21,2) -> 0 | X21: Equipos: | AF21: FLETE | AG21: KG | AH21: 631.05 | AI21: 1.9600688 | AJ21: =+ROUND(AH21*AI21,2) -> 1236.9 | AW21: COSTO NETO TOTAL - D - | AY21: (A+B+C) | BA21: =+BA12+BA17+BA20 -> 14126028 | BD21: SUBTOTAL EQUIPOS - C - | BH21: =SUM(BH19:BH20) -> 330000 | BL21: =+$E$64 -> 12 | BM21: =$F$64 -> SOLADO Y ZOCALO | BN21: =+$K$64*$BP$2 -> 10821114 | BO21: =BN21/$BN$30 -> 0.035781181
E22: 2.7 | F22: RETIRO DE ESCOMBROS | G22: Gl | H22: 1 | I22: =+$T$173 -> 107122.22 | J22: =ROUND(I22*H22,2) -> 107122.22 | L22: =+J22/$K$120 -> 0.00056282953 | M22: =+L22 -> 0.00056282953 | P22: SUBTOTAL EQUIPOS - C - | T22: =SUM(T19:T21) -> 0 | X22: FLETE | Y22: KG | Z22: 141.25 | AA22: 1.9600688 | AB22: =+ROUND(Z22*AA22,2) -> 276.86 | AF22: SUBTOTAL EQUIPOS - C - | AJ22: =SUM(AJ21:AJ21) -> 1236.9 | AN22: 10 - TABIQUE DE PLACAS DE YESO | BD22: COSTO NETO TOTAL - D - | BF22: (A+B+C) | BH22: =+BH12+BH17+BH21 -> 492564 | BL22: =+$E$72 -> 13 | BM22: =$F$72 -> CARPINTERIA | BN22: =+$K$72*$BP$2 -> 22023711 | BO22: =BN22/$BN$30 -> 0.072823781
E23: 3 | F23: MOVIMIENTO DE SUELO | K23: =SUM(J24) -> 71230.37 | L23: =+K23/$K$120 -> 0.0003742506 | P23: COSTO NETO TOTAL - D - | R23: (A+B+C) | T23: =+T11+T16+T22 -> 121923 | X23: SUBTOTAL EQUIPOS - C - | AB23: =SUM(AB22:AB22) -> 276.86 | AF23: COSTO NETO TOTAL - D - | AH23: (A+B+C) | AJ23: =+AJ14+AJ19+AJ22 -> 39322.02 | AN23: 10.2 - TABIQUE DE PLACA DE YESO C/AISL | AR23: =$G$60 -> m2 | AS23: =$H$60 -> 153 | AW23: 16 - AIRE ACONDICIONADO | BL23: =+$E$90 -> 14 | BM23: =$F$90 -> INSTALACION ELECTRICA | BN23: =+$K$90*$BP$2 -> 1.3170524e+08 | BO23: =BN23/$BN$30 -> 0.4354976
E24: 3.1 | F24: EXCAVACION PARA FUNDACION PARA ASCENSOR | G24: m3 | H24: 8.5215 | I24: =+$T$191 -> 8358.9 | J24: =ROUND(I24*H24,2) -> 71230.37 | L24: =+J24/$K$120 -> 0.0003742506 | M24: =+L24 -> 0.0003742506 | X24: COSTO NETO TOTAL - D - | Z24: (A+B+C) | AB24: =+AB15+AB20+AB23 -> 119442.22 | AW24: 16.1 - RETIRO DE EQUIPOS | BA24: =$G$103 -> Gl | BB24: =$H$103 -> 1 | BD24: 18 - VARIOS | BL24: =+$E$100 -> 15 | BM24: =$F$100 -> INSTALACIÓN ELECTROMECÁNICA | BN24: =+$K$100*$BP$2 -> 22445777 | BO24: =BN24/$BN$30 -> 0.074219387
E25: 4 | F25: ESTRUCTURA RESISTENTE | K25: =SUM(J26:J39) -> 13372883 | L25: =+K25/$K$120 -> 0.070262299 | P25: 1 - TRABAJOS PREPARATORIOS | AF25: 5 - MAMPOSTERIA | AN25: DESCRIPCION | AO25: UNIDAD | AP25: CANTIDAD | AQ25: PRECIO | AR25: Subtotal | AS25: FLETE | BD25: 18.2 - CARTELES INDICADORES DE LOCAL | BH25: =$G$113 -> Un | BI25: =$H$113 -> 17 | BL25: =+$E$102 -> 16 | BM25: =$F$102 -> AIRE ACONDICIONADO | BN25: =+$K$102*$BP$2 -> 36155129 | BO25: =BN25/$BN$30 -> 0.11955084
E26: 4.1 | F26: ESTRUTURA DE HºAº | P26: 1.2 - CARTEL DE OBRA | T26: =$G$14 -> m2 | U26: =$H$14 -> 8.64 | X26: 4 - ESTRUCTURA RESISTENTE | AF26: 5.2 - MAMP. ARMADA LAD.COMUN - 0,18 | AJ26: =$G$42 -> m3 | AK26: =$H$42 -> 1.045 | AN26: Materiales: | AW26: DESCRIPCION | AX26: UNIDAD | AY26: CANTIDAD | AZ26: PRECIO | BA26: Subtotal | BB26: FLETE | BL26: =+$E$106 -> 17 | BM26: =$F$106 -> PINTURA | BN26: =+$K$106*$BP$2 -> 7335522.6 | BO26: =BN26/$BN$30 -> 0.024255698
E27: 4.1.1 | F27: HºAº PARA BASE ASCENSOR - H30 | G27: m3 | H27: 1.878225 | I27: =+$AB$24 -> 119442.22 | J27: =ROUND(I27*H27,2) -> 224339.36 | L27: =+J27/$K$120 -> 0.0011786986 | M27: =+L27 -> 0.0011786986 | X27: 4.2.1 - ESTRCTURA METALICA ASCENSOR | AB27: =$G$29 -> Gl | AC27: =$H$29 -> 1 | AN27: TABIQUE DE PLACA DE YESO C/AISL | AO27: gl | AP27: 1.05 | AQ27: 7334.985 | AR27: =+ROUND(AP27*AQ27,2) -> 7701.73 | AW27: Materiales: | BD27: DESCRIPCION | BE27: UNIDAD | BF27: CANTIDAD | BG27: PRECIO | BH27: Subtotal | BI27: FLETE | BL27: =+$E$111 -> 18 | BM27: =$F$111 -> VARIOS | BN27: =+$K$111*$BP$2 -> 12545939 | BO27: =BN27/$BN$30 -> 0.041484504
E28: 4.2 | F28: ESTRUTURA METALICA | P28: DESCRIPCION | Q28: UNIDAD | R28: CANTIDAD | S28: PRECIO | T28: Subtotal | U28: FLETE | AF28: DESCRIPCION | AG28: UNIDAD | AH28: CANTIDAD | AI28: PRECIO | AJ28: Subtotal | AK28: FLETE | AN28: Varios, carga, descarga y desperdicio | AO28: gl | AP28: 0.03 | AQ28: 7701.73 | AR28: =+ROUND(AP28*AQ28,2) -> 231.05 | BA28: =+ROUND(AY28*AZ28,2) -> 0 | BD28: Materiales:
E29: 4.2.1 | F29: ESTRCTURA METALICA ASCENSOR | G29: Gl | H29: 1 | I29: =+$AB$43 -> 5849381 | J29: =ROUND(I29*H29,2) -> 5849381 | L29: =+J29/$K$120 -> 0.03073316 | M29: =+L29 -> 0.03073316 | P29: Materiales: | X29: DESCRIPCION | Y29: UNIDAD | Z29: CANTIDAD | AA29: PRECIO | AB29: Subtotal | AC29: FLETE | AF29: Materiales: | AN29: SUBTOTAL MATERIALES - A - | AR29: =SUM(AR27:AR28) -> 7932.78 | BA29: =+ROUND(AY29*AZ29,2) -> 0 | BD29: 18.2 - CARTELES INDICADORES DE LOCAL | BE29: UN | BF29: 1 | BG29: 1177 | BH29: =ROUND((BG29*BF29),2) -> 1177
E30: 4.2.3 | F30: COLUMNAS METALICAS -Co- ESTUDIO-CON REFUERZO DE APOYOS SOBRE LOSAS PRETENSADAS | G30: ml | H30: 98.13 | I30: =+$AB$62 -> 18257.18 | J30: =ROUND(I30*H30,2) -> 1791577.1 | L30: =+J30/$K$120 -> 0.0094131029 | M30: =+L30 -> 0.0094131029 | P30: Cartel de Obra | Q30: m2 | R30: 1 | S30: 16497.585 | T30: =+ROUND(R30*S30,2) -> 16497.58 | X30: Materiales: | AF30: Ladrillos Comunes | AG30: Un | AH30: 290 | AI30: 37.45 | AJ30: =+ROUND(AH30*AI30,2) -> 10860.5 | AN30: Mano de Obra: | AS30: =+AR27*AS23 -> 1178364.7 | AW30: Varios, carga, descarga y desperdicio | AX30: gl | AY30: 0.03 | AZ30: 0 | BA30: =+ROUND(AY30*AZ30,2) -> 0 | BD30: Varios, carga, descarga y desperdicio | BE30: gl | BF30: 0.03 | BG30: 1177 | BH30: =ROUND((BG30*BF30),2) -> 35.31 | BN30: =SUM(BN10:BN29) -> 3.0242472e+08 | BO30: =SUM(BO10:BO29) -> 1
E31: 4.2.4 | F31: VIGAS METALICAS - VM1-ESTUDIO | G31: ml | H31: 43.67 | I31: =+$AB$81 -> 7920.91 | J31: =ROUND(I31*H31,2) -> 345906.14 | L31: =+J31/$K$120 -> 0.0018174212 | M31: =+L31 -> 0.0018174212 | P31: Varios, carga, descarga y desperdicio | Q31: gl | R31: 0.03 | S31: 16497.58 | T31: =+ROUND(R31*S31,2) -> 494.93 | X31: 4.2.1 - ESTRCTURA METALICA ASCENSOR | Y31: GL | Z31: 1 | AA31: 4441229 | AB31: =+ROUND(Z31*AA31,2) -> 4441229 | AF31: Cemento | AG31: Kg | AH31: 90 | AI31: 26.528938 | AJ31: =+ROUND(AH31*AI31,2) -> 2387.6 | AN31: Oficial | AO31: hs | AQ31: 1600.8 | AR31: =+ROUND(AP31*AQ31,2) -> 0 | AW31: SUBTOTAL MATERIALES - A - | BA31: =SUM(BA28:BA30) -> 0 | BD31: SUBTOTAL MATERIALES - A - | BH31: =SUM(BH29:BH30) -> 1212.31
E32: 4.2.5 | F32: VIGAS METALICAS - VM2-ESTUDIO | G32: ml | H32: 19.36 | I32: =+$AB$100 -> 14954.19 | J32: =ROUND(I32*H32,2) -> 289513.12 | L32: =+J32/$K$120 -> 0.0015211273 | M32: =+L32 -> 0.0015211273 | P32: SUBTOTAL MATERIALES - A - | T32: =SUM(T30:T31) -> 16992.51 | X32: ANCLANJES | Y32: GL | Z32: 1 | AA32: 62300 | AB32: =+ROUND(Z32*AA32,2) -> 62300 | AF32: Arena | AG32: M3 | AH32: 0.36 | AI32: 2066.1157 | AJ32: =+ROUND(AH32*AI32,2) -> 743.8 | AN32: Ayudante | AO32: hs | AQ32: 1354.7 | AR32: =+ROUND(AP32*AQ32,2) -> 0 | AW32: Mano de Obra: | BD32: Mano de Obra:
E33: 4.2.6 | F33: VIGAS METALICAS - VM3-AG.FOCO | G33: ml | H33: 13.64 | I33: =+$AB$119 -> 6605.05 | J33: =ROUND(I33*H33,2) -> 90092.88 | L33: =+J33/$K$120 -> 0.00047335588 | M33: =+L33 -> 0.00047335588 | P33: Mano de Obra: | X33: Varios, carga, descarga y desperdicio | Y33: gl | Z33: 0.03 | AA33: 1351058.7 | AB33: =+ROUND(Z33*AA33,2) -> 40531.76 | AF33: Hierro | AG33: Kg | AH33: 1.785 | AI33: 27.236208 | AJ33: =+ROUND(AH33*AI33,2) -> 48.62 | AW33: Oficial | AX33: hs | AY33: 40 | AZ33: 1600.8 | BA33: =+ROUND(AY33*AZ33,2) -> 64032 | BD33: Oficial | BE33: hs | BF33: 0.3 | BG33: 1600.8 | BH33: =+ROUND(BF33*BG33,2) -> 480.24 | BN33: =+$K$128 -> 3.0242472e+08 | BO33: =BO30-1 -> 0
E34: 4.2.7 | F34: VIGAS METALICAS - VM4-AG.FOCO | G34: ml | H34: 22.22 | I34: =+$AB$138 -> 12322.48 | J34: =ROUND(I34*H34,2) -> 273805.51 | L34: =+J34/$K$120 -> 0.0014385981 | M34: =+L34 -> 0.0014385981 | P34: Oficial | Q34: hs | R34: 0.6 | S34: 1600.8 | T34: =+ROUND(R34*S34,2) -> 960.48 | X34: SUBTOTAL MATERIALES - A - | AB34: =SUM(AB31:AB33) -> 4544060.8 | AF34: Varios, carga, descarga y desperdicio | AG34: gl | AH34: 0.03 | AI34: 14040.52 | AJ34: =+ROUND(AH34*AI34,2) -> 421.22 | AN34: SUBTOTAL MANO DE OBRA - B - | AR34: =SUM(AR31:AR33) -> 0 | AW34: Ayudante | AX34: hs | AY34: 40 | AZ34: 1354.7 | BA34: =+ROUND(AY34*AZ34,2) -> 54188 | BD34: Ayudante | BE34: hs | BG34: 1354.7 | BH34: =+ROUND(BF34*BG34,2) -> 0 | BN34: =+BN33-BN30 -> 0
E35: 4.2.8 | F35: VIGAS METALICAS - VM6-AG.FOCO | G35: ml | H35: 13.2 | I35: =+$AB$176 -> 11701.2 | J35: =ROUND(I35*H35,2) -> 154455.84 | L35: =+J35/$K$120 -> 0.00081152451 | M35: =+L35 -> 0.00081152451 | P35: Ayudante | Q35: hs | R35: 0.6 | S35: 1354.7 | T35: =+ROUND(R35*S35,2) -> 812.82 | X35: Mano de Obra: | AF35: SUBTOTAL MATERIALES - A - | AJ35: =SUM(AJ30:AJ34) -> 14461.74 | AN35: Equipos:
E36: 4.2.9 | F36: VIGAS METALICAS - VM7-ESTUDIO | G36: ml | H36: 26.4 | I36: =+$AB$157 -> 12322.48 | J36: =ROUND(I36*H36,2) -> 325313.47 | L36: =+J36/$K$120 -> 0.0017092255 | M36: =+L36 -> 0.0017092255 | X36: Oficial | Y36: hs | Z36: 440 | AA36: 1600.8 | AB36: =+ROUND(Z36*AA36,2) -> 704352 | AF36: Mano de Obra: | AN36: FLETE | AO36: KG | AP36: 40 | AQ36: 1.9600688 | AR36: =+ROUND(AP36*AQ36,2) -> 78.4 | AW36: SUBTOTAL MANO DE OBRA - B - | BA36: =SUM(BA33:BA35) -> 118220 | BD36: SUBTOTAL MANO DE OBRA - B - | BH36: =SUM(BH33:BH35) -> 480.24
E37: 4.2.10 | F37: VIGAS METALICAS - VM5-ESTUDIO - REFUERZO SUPERIOR | G37: ml | H37: 15.98 | I37: =+$AB$195 -> 148090.25 | J37: =ROUND(I37*H37,2) -> 2366482.2 | L37: =+J37/$K$120 -> 0.012433705 | M37: =+L37 -> 0.012433705 | P37: SUBTOTAL MANO DE OBRA - B - | T37: =SUM(T34:T36) -> 1773.3 | X37: Ayudante | Y37: hs | Z37: 440 | AA37: 1354.7 | AB37: =+ROUND(Z37*AA37,2) -> 596068 | AF37: Oficial | AG37: hs | AH37: 8 | AI37: 1600.8 | AJ37: =+ROUND(AH37*AI37,2) -> 12806.4 | AN37: SUBTOTAL EQUIPOS - C - | AR37: =SUM(AR36:AR36) -> 78.4 | AW37: Equipos: | BD37: Equipos:
E38: 4.2.11 | F38: CORREAS METALICAS - ENTREPISO - ESTUDIO-AG.FOCO | G38: ml | H38: 280.5 | I38: =+$AB$214 -> 4119 | J38: =ROUND(I38*H38,2) -> 1155379.5 | L38: =+J38/$K$120 -> 0.0060704651 | M38: =+L38 -> 0.0060704651 | AF38: Ayudante | AG38: hs | AH38: 8 | AI38: 1354.7 | AJ38: =+ROUND(AH38*AI38,2) -> 10837.6 | AN38: COSTO NETO TOTAL - D - | AP38: (A+B+C) | AR38: =+AR29+AR34+AR37 -> 8011.18 | AW38: FLETE | AX38: KG | AY38: 360 | AZ38: 1.9600688 | BA38: =+ROUND(AY38*AZ38,2) -> 705.62 | BD38: FLETE | BE38: KG | BF38: 0 | BG38: 1.9600688 | BH38: =+ROUND(BF38*BG38,2) -> 0
E39: 4.2.12 | F39: CORREAS PARA CUBIERTA NUEVA-AG.FOCO | G39: ml | H39: 123 | I39: =+$AB$214 -> 4119 | J39: =ROUND(I39*H39,2) -> 506637 | L39: =+J39/$K$120 -> 0.0026619152 | M39: =+L39 -> 0.0026619152 | P39: Equipos: | X39: SUBTOTAL MANO DE OBRA - B - | AB39: =SUM(AB36:AB38) -> 1300420 | AW39: SUBTOTAL EQUIPOS - C - | BA39: =SUM(BA38:BA38) -> 705.62 | BH39: =+ROUND(BF39*BG39,2) -> 0
E40: 5 | F40: MAMPOSTERIA | K40: =SUM(J41:J44) -> 1459132.3 | L40: =+K40/$K$120 -> 0.0076664091 | P40: FLETE | Q40: KG | R40: 60 | S40: 1.9600688 | T40: =+ROUND(R40*S40,2) -> 117.6 | X40: Equipos: | AF40: SUBTOTAL MANO DE OBRA - B - | AJ40: =SUM(AJ37:AJ39) -> 23644 | AN40: 11 - CIELORRASO | AW40: COSTO NETO TOTAL - D - | AY40: (A+B+C) | BA40: =+BA31+BA36+BA39 -> 118925.62 | BD40: SUBTOTAL EQUIPOS - C - | BH40: =SUM(BH38:BH39) -> 0
E41: 5.1 | F41: MAMP. ELEVACION LAD.COMUN - 0,18 | G41: m3 | H41: 35.11 | I41: =+$AJ$23 -> 39322.02 | J41: =ROUND(I41*H41,2) -> 1380596.1 | L41: =+J41/$K$120 -> 0.007253773 | M41: =+L41 -> 0.007253773 | P41: Equipos - Hormigonera | Q41: gl | S41: 686.94 | T41: =+ROUND(R41*S41,2) -> 0 | X41: FLETE | Y41: KG | Z41: 2500 | AA41: 1.9600688 | AB41: =+ROUND(Z41*AA41,2) -> 4900.17 | AF41: Equipos: | AN41: 11.1 - CIELORRASO DESMONTABLE PLACA EXSOUND C/LV 70mm | AR41: =$G$62 -> m2 | AS41: =$H$62 -> 145.5 | BD41: COSTO NETO TOTAL - D - | BF41: (A+B+C) | BH41: =+BH31+BH36+BH40 -> 1692.55
...

Sheet PLAN DE TRABAJO
B8: P L A N D E T R A B A J O S Y D E I N V E R S I O N E S
B10: ESTUDIO TV
B11: LOCALIDAD: RESISTENCIA
B12: EMPRESA: I.L.A.G. CONSTRUCCIONES
D14: MONTO | E14: %
B15: No | C15: D E S C R I P C I O N | D15: DEL | E15: 0 | F15: 1 | G15: 2 | H15: 3
D16: ITEM | E16: INC.
B18: =+'PPTO ESTUDIO TV'!BL10 -> 1 | C18: =+'PPTO ESTUDIO TV'!BM10 -> TRABAJOS PREPARATORIOS | D18: =+'PPTO ESTUDIO TV'!BN10 -> 452975.52 | E18: =+'PPTO ESTUDIO TV'!BO10 -> 0.0014978125 | F18: 1 | I18: =SUM(F18:H18) -> 1
B19: =+'PPTO ESTUDIO TV'!BL11 -> 2 | C19: =+'PPTO ESTUDIO TV'!BM11 -> DEMOLICIONES | D19: =+'PPTO ESTUDIO TV'!BN11 -> 622029.59 | E19: =+'PPTO ESTUDIO TV'!BO11 -> 0.0020568081 | F19: 0.95 | G19: 0.05 | H19: 0 | I19: =SUM(F19:H19) -> 1
B20: =+'PPTO ESTUDIO TV'!BL12 -> 3 | C20: =+'PPTO ESTUDIO TV'!BM12 -> MOVIMIENTO DE SUELO | D20: =+'PPTO ESTUDIO TV'!BN12 -> 113182.63 | E20: =+'PPTO ESTUDIO TV'!BO12 -> 0.0003742506 | F20: 0.95 | G20: 0.05 | H20: 0 | I20: =SUM(F20:H20) -> 1
B21: =+'PPTO ESTUDIO TV'!BL13 -> 4 | C21: =+'PPTO ESTUDIO TV'!BM13 -> ESTRUCTURA RESISTENTE | D21: =+'PPTO ESTUDIO TV'!BN13 -> 21249056 | E21: =+'PPTO ESTUDIO TV'!BO13 -> 0.070262299 | F21: 0.95 | G21: 0.05 | H21: 0 | I21: =SUM(F21:H21) -> 1
B22: =+'PPTO ESTUDIO TV'!BL14 -> 5 | C22: =+'PPTO ESTUDIO TV'!BM14 -> MAMPOSTERIA | D22: =+'PPTO ESTUDIO TV'!BN14 -> 2318511.6 | E22: =+'PPTO ESTUDIO TV'!BO14 -> 0.0076664091 | F22: 0.75 | G22: 0.25 | H22: 0 | I22: =SUM(F22:H22) -> 1
B23: =+'PPTO ESTUDIO TV'!BL15 -> 6 | C23: =+'PPTO ESTUDIO TV'!BM15 -> AISLACION | D23: =+'PPTO ESTUDIO TV'!BN15 -> 2548672 | E23: =+'PPTO ESTUDIO TV'!BO15 -> 0.0084274593 | F23: 0.2 | G23: 0.5 | H23: 0.3 | I23: =SUM(F23:H23) -> 1
B24: =+'PPTO ESTUDIO TV'!BL16 -> 7 | C24: =+'PPTO ESTUDIO TV'!BM16 -> REVOQUE | D24: =+'PPTO ESTUDIO TV'!BN16 -> 2406120.7 | E24: =+'PPTO ESTUDIO TV'!BO16 -> 0.0079560982 | F24: 0.2 | G24: 0.5 | H24: 0.3 | I24: =SUM(F24:H24) -> 1
B25: =+'PPTO ESTUDIO TV'!BL17 -> 8 | C25: =+'PPTO ESTUDIO TV'!BM17 -> REVESTIMIENTO | D25: =+'PPTO ESTUDIO TV'!BN17 -> 34097.032 | E25: =+'PPTO ESTUDIO TV'!BO17 -> 0.00011274552 | G25: 0.65 | H25: 0.35 | I25: =SUM(F25:H25) -> 1
B26: =+'PPTO ESTUDIO TV'!BL18 -> 9 | C26: =+'PPTO ESTUDIO TV'!BM18 -> CUBIERTA DE CHº Gº | D26: =+'PPTO ESTUDIO TV'!BN18 -> 1304592.9 | E26: =+'PPTO ESTUDIO TV'!BO18 -> 0.0043137775 | G26: 0.7 | H26: 0.3 | I26: =SUM(F26:H26) -> 1
B27: =+'PPTO ESTUDIO TV'!BL19 -> 10 | C27: =+'PPTO ESTUDIO TV'!BM19 -> TABIQUE DE PLACAS DE YESO | D27: =+'PPTO ESTUDIO TV'!BN19 -> 21201331 | E27: =+'PPTO ESTUDIO TV'!BO19 -> 0.07010449 | G27: 0.6 | H27: 0.4 | I27: =SUM(F27:H27) -> 1
B28: =+'PPTO ESTUDIO TV'!BL20 -> 11 | C28: =+'PPTO ESTUDIO TV'!BM20 -> CIELORRASO | D28: =+'PPTO ESTUDIO TV'!BN20 -> 7141716 | E28: =+'PPTO ESTUDIO TV'!BO20 -> 0.023614856 | G28: 0.6 | H28: 0.4 | I28: =SUM(F28:H28) -> 1
B29: =+'PPTO ESTUDIO TV'!BL21 -> 12 | C29: =+'PPTO ESTUDIO TV'!BM21 -> SOLADO Y ZOCALO | D29: =+'PPTO ESTUDIO TV'!BN21 -> 10821114 | E29: =+'PPTO ESTUDIO TV'!BO21 -> 0.035781181 | G29: 0.65 | H29: 0.35 | I29: =SUM(F29:H29) -> 1
B30: =+'PPTO ESTUDIO TV'!BL22 -> 13 | C30: =+'PPTO ESTUDIO TV'!BM22 -> CARPINTERIA | D30: =+'PPTO ESTUDIO TV'!BN22 -> 22023711 | E30: =+'PPTO ESTUDIO TV'!BO22 -> 0.072823781 | G30: 0.55 | H30: 0.45 | I30: =SUM(F30:H30) -> 1
B31: =+'PPTO ESTUDIO TV'!BL23 -> 14 | C31: =+'PPTO ESTUDIO TV'!BM23 -> INSTALACION ELECTRICA | D31: =+'PPTO ESTUDIO TV'!BN23 -> 1.3170524e+08 | E31: =+'PPTO ESTUDIO TV'!BO23 -> 0.4354976 | F31: 0.2 | G31: 0.4 | H31: 0.4 | I31: =SUM(F31:H31) -> 1
B32: =+'PPTO ESTUDIO TV'!BL24 -> 15 | C32: =+'PPTO ESTUDIO TV'!BM24 -> INSTALACIÓN ELECTROMECÁNICA | D32: =+'PPTO ESTUDIO TV'!BN24 -> 22445777 | E32: =+'PPTO ESTUDIO TV'!BO24 -> 0.074219387 | G32: 0.6 | H32: 0.4 | I32: =SUM(F32:H32) -> 1
B33: =+'PPTO ESTUDIO TV'!BL25 -> 16 | C33: =+'PPTO ESTUDIO TV'!BM25 -> AIRE ACONDICIONADO | D33: =+'PPTO ESTUDIO TV'!BN25 -> 36155129 | E33: =+'PPTO ESTUDIO TV'!BO25 -> 0.11955084 | F33: 0.2 | G33: 0.4 | H33: 0.4 | I33: =SUM(F33:H33) -> 1
B34: =+'PPTO ESTUDIO TV'!BL26 -> 17 | C34: =+'PPTO ESTUDIO TV'!BM26 -> PINTURA | D34: =+'PPTO ESTUDIO TV'!BN26 -> 7335522.6 | E34: =+'PPTO ESTUDIO TV'!BO26 -> 0.024255698 | G34: 0.5 | H34: 0.5 | I34: =SUM(F34:H34) -> 1
B35: =+'PPTO ESTUDIO TV'!BL27 -> 18 | C35: =+'PPTO ESTUDIO TV'!BM27 -> VARIOS | D35: =+'PPTO ESTUDIO TV'!BN27 -> 12545939 | E35: =+'PPTO ESTUDIO TV'!BO27 -> 0.041484504 | F35: 0.3 | G35: 0.3 | H35: 0.4 | I35: =SUM(F35:H35) -> 1
C36: =+'PPTO ESTUDIO TV'!BM28 -> 0 | I36: =SUM(F36:H36) -> 0
A38: =+'PPTO ESTUDIO TV'!K128 -> 3.0242472e+08 | C38: T O T A L | D38: =SUM(D17:D37) -> 3.0242472e+08 | E38: =SUM(E17:E37) -> 1
B40: =B8 -> P L A N D E T R A B A J O S Y D E I N V E R S I O N E S
B41: =B9 -> 0
B42: =B10 -> ESTUDIO TV
B43: =B11 -> LOCALIDAD: RESISTENCIA
B44: =B12 -> EMPRESA: I.L.A.G. CONSTRUCCIONES
E46: %
B47: No | C47: D E S C R I P C I O N | E47: 0 | F47: =+F15 -> 1 | G47: =+G15 -> 2 | H47: =+H15 -> 3
E48: INC.
B51: =B18 -> 1 | C51: =C18 -> TRABAJOS PREPARATORIOS | D51: =+D18 -> 452975.52 | E51: =+E18 -> 0.0014978125 | F51: =F18*$E51 -> 0.0014978125 | G51: =G18*$E51 -> 0 | H51: =H18*$E51 -> 0 | I51: =SUM(F51:H51)-E51 -> 0
B52: =B19 -> 2 | C52: =C19 -> DEMOLICIONES | D52: =+D19 -> 622029.59 | E52: =+E19 -> 0.0020568081 | F52: =F19*$E52 -> 0.0019539677 | G52: =G19*$E52 -> 0.0001028404 | H52: =H19*$E52 -> 0 | I52: =SUM(F52:H52)-E52 -> 0
B53: =B20 -> 3 | C53: =C20 -> MOVIMIENTO DE SUELO | D53: =+D20 -> 113182.63 | E53: =+E20 -> 0.0003742506 | F53: =F20*$E53 -> 0.00035553807 | G53: =G20*$E53 -> 1.871253e-05 | H53: =H20*$E53 -> 0 | I53: =SUM(F53:H53)-E53 -> 0
B54: =B21 -> 4 | C54: =C21 -> ESTRUCTURA RESISTENTE | D54: =+D21 -> 21249056 | E54: =+E21 -> 0.070262299 | F54: =F21*$E54 -> 0.066749184 | G54: =G21*$E54 -> 0.003513115 | H54: =H21*$E54 -> 0 | I54: =SUM(F54:H54)-E54 -> 0
B55: =B22 -> 5 | C55: =C22 -> MAMPOSTERIA | D55: =+D22 -> 2318511.6 | E55: =+E22 -> 0.0076664091 | F55: =F22*$E55 -> 0.0057498068 | G55: =G22*$E55 -> 0.0019166023 | H55: =H22*$E55 -> 0 | I55: =SUM(F55:H55)-E55 -> 0
...
